test_anagram (__main__.TestExercice) ... ERROR
test_doubles (__main__.TestExercice) ... FAIL
test_grades (__main__.TestExercice) ... FAIL
test_histogram (__main__.TestExercice) ... FAIL
test_order (__main__.TestExercice) ... ERROR

======================================================================
ERROR: test_anagram (__main__.TestExercice)
----------------------------------------------------------------------
Traceback (most recent call last):
  File "test_exercice.py", line 35, in test_anagram
    output = [exercice.anagrams(v) for v in words]
  File "test_exercice.py", line 35, in <listcomp>
    output = [exercice.anagrams(v) for v in words]
  File "/home/runner/work/c01_ch6_exercices-Flextapes/c01_ch6_exercices-Flextapes/exercice.py", line 26, in anagrams
    return liste1 == liste2
UnboundLocalError: local variable 'liste1' referenced before assignment

======================================================================
ERROR: test_order (__main__.TestExercice)
----------------------------------------------------------------------
Traceback (most recent call last):
  File "test_exercice.py", line 19, in test_order
    output = [exercice.order(v) for v in values]
  File "test_exercice.py", line 19, in <listcomp>
    output = [exercice.order(v) for v in values]
  File "/home/runner/work/c01_ch6_exercices-Flextapes/c01_ch6_exercices-Flextapes/exercice.py", line 9, in order
    return values == sorted(value)
UnboundLocalError: local variable 'value' referenced before assignment

======================================================================
FAIL: test_doubles (__main__.TestExercice)
----------------------------------------------------------------------
Traceback (most recent call last):
  File "test_exercice.py", line 55, in test_doubles
    'Erreur dans les doublons'
AssertionError: Lists differ: [False, False] != [False, True]

First differing element 1:
False
True

- [False, False]
+ [False, True] : Erreur dans les doublons

======================================================================
FAIL: test_grades (__main__.TestExercice)
----------------------------------------------------------------------
Traceback (most recent call last):
  File "test_exercice.py", line 69, in test_grades
    'Erreur dans les notes'
AssertionError: [{}] is not an instance of <class 'dict'> : First argument is not a dictionary

======================================================================
FAIL: test_histogram (__main__.TestExercice)
----------------------------------------------------------------------
Traceback (most recent call last):
  File "test_exercice.py", line 84, in test_histogram
    'Erreur dans les histogrammes'
AssertionError: [({}, []), ({}, [])] is not an instance of <class 'dict'> : First argument is not a dictionary

----------------------------------------------------------------------
Ran 5 tests in 0.001s

FAILED (failures=3, errors=2)
